{
 "cells": [
  {
   "cell_type": "code",
   "execution_count": 1,
   "id": "c637b6af",
   "metadata": {},
   "outputs": [
    {
     "name": "stdout",
     "output_type": "stream",
     "text": [
      "Collecting pandas_profiling\n",
      "  Downloading pandas_profiling-3.2.0-py2.py3-none-any.whl (262 kB)\n",
      "\u001b[K     |████████████████████████████████| 262 kB 21 kB/s eta 0:00:01\n",
      "\u001b[?25hRequirement already satisfied: scipy>=1.4.1 in /opt/anaconda3/lib/python3.9/site-packages (from pandas_profiling) (1.7.1)\n",
      "Requirement already satisfied: matplotlib>=3.2.0 in /opt/anaconda3/lib/python3.9/site-packages (from pandas_profiling) (3.4.3)\n",
      "Requirement already satisfied: pandas!=1.0.0,!=1.0.1,!=1.0.2,!=1.1.0,>=0.25.3 in /opt/anaconda3/lib/python3.9/site-packages (from pandas_profiling) (1.3.4)\n",
      "Requirement already satisfied: PyYAML>=5.0.0 in /opt/anaconda3/lib/python3.9/site-packages (from pandas_profiling) (6.0)\n",
      "Requirement already satisfied: numpy>=1.16.0 in /opt/anaconda3/lib/python3.9/site-packages (from pandas_profiling) (1.20.3)\n",
      "Collecting visions[type_image_path]==0.7.4\n",
      "  Downloading visions-0.7.4-py3-none-any.whl (102 kB)\n",
      "\u001b[K     |████████████████████████████████| 102 kB 8.2 kB/s ta 0:00:02\n",
      "\u001b[?25hCollecting htmlmin>=0.1.12\n",
      "  Downloading htmlmin-0.1.12.tar.gz (19 kB)\n",
      "Requirement already satisfied: jinja2>=2.11.1 in /opt/anaconda3/lib/python3.9/site-packages (from pandas_profiling) (2.11.3)\n",
      "Collecting phik>=0.11.1\n",
      "  Downloading phik-0.12.2-cp39-cp39-macosx_10_13_x86_64.whl (694 kB)\n",
      "\u001b[K     |████████████████████████████████| 694 kB 16 kB/s eta 0:00:010\n",
      "\u001b[?25hRequirement already satisfied: tqdm>=4.48.2 in /opt/anaconda3/lib/python3.9/site-packages (from pandas_profiling) (4.62.3)\n",
      "Collecting pydantic>=1.8.1\n",
      "  Downloading pydantic-1.9.1-cp39-cp39-macosx_10_9_x86_64.whl (3.0 MB)\n",
      "\u001b[K     |███▋                            | 337 kB 5.7 kB/s eta 0:07:39\u001b[31mERROR: Exception:\n",
      "Traceback (most recent call last):\n",
      "  File \"/opt/anaconda3/lib/python3.9/site-packages/pip/_vendor/urllib3/response.py\", line 438, in _error_catcher\n",
      "    yield\n",
      "  File \"/opt/anaconda3/lib/python3.9/site-packages/pip/_vendor/urllib3/response.py\", line 519, in read\n",
      "    data = self._fp.read(amt) if not fp_closed else b\"\"\n",
      "  File \"/opt/anaconda3/lib/python3.9/site-packages/pip/_vendor/cachecontrol/filewrapper.py\", line 62, in read\n",
      "    data = self.__fp.read(amt)\n",
      "  File \"/opt/anaconda3/lib/python3.9/http/client.py\", line 462, in read\n",
      "    n = self.readinto(b)\n",
      "  File \"/opt/anaconda3/lib/python3.9/http/client.py\", line 506, in readinto\n",
      "    n = self.fp.readinto(b)\n",
      "  File \"/opt/anaconda3/lib/python3.9/socket.py\", line 704, in readinto\n",
      "    return self._sock.recv_into(b)\n",
      "  File \"/opt/anaconda3/lib/python3.9/ssl.py\", line 1241, in recv_into\n",
      "    return self.read(nbytes, buffer)\n",
      "  File \"/opt/anaconda3/lib/python3.9/ssl.py\", line 1099, in read\n",
      "    return self._sslobj.read(len, buffer)\n",
      "socket.timeout: The read operation timed out\n",
      "\n",
      "During handling of the above exception, another exception occurred:\n",
      "\n",
      "Traceback (most recent call last):\n",
      "  File \"/opt/anaconda3/lib/python3.9/site-packages/pip/_internal/cli/base_command.py\", line 173, in _main\n",
      "    status = self.run(options, args)\n",
      "  File \"/opt/anaconda3/lib/python3.9/site-packages/pip/_internal/cli/req_command.py\", line 203, in wrapper\n",
      "    return func(self, options, args)\n",
      "  File \"/opt/anaconda3/lib/python3.9/site-packages/pip/_internal/commands/install.py\", line 315, in run\n",
      "    requirement_set = resolver.resolve(\n",
      "  File \"/opt/anaconda3/lib/python3.9/site-packages/pip/_internal/resolution/resolvelib/resolver.py\", line 94, in resolve\n",
      "    result = self._result = resolver.resolve(\n",
      "  File \"/opt/anaconda3/lib/python3.9/site-packages/pip/_vendor/resolvelib/resolvers.py\", line 472, in resolve\n",
      "    state = resolution.resolve(requirements, max_rounds=max_rounds)\n",
      "  File \"/opt/anaconda3/lib/python3.9/site-packages/pip/_vendor/resolvelib/resolvers.py\", line 366, in resolve\n",
      "    failure_causes = self._attempt_to_pin_criterion(name)\n",
      "  File \"/opt/anaconda3/lib/python3.9/site-packages/pip/_vendor/resolvelib/resolvers.py\", line 212, in _attempt_to_pin_criterion\n",
      "    criteria = self._get_updated_criteria(candidate)\n",
      "  File \"/opt/anaconda3/lib/python3.9/site-packages/pip/_vendor/resolvelib/resolvers.py\", line 203, in _get_updated_criteria\n",
      "    self._add_to_criteria(criteria, requirement, parent=candidate)\n",
      "  File \"/opt/anaconda3/lib/python3.9/site-packages/pip/_vendor/resolvelib/resolvers.py\", line 172, in _add_to_criteria\n",
      "    if not criterion.candidates:\n",
      "  File \"/opt/anaconda3/lib/python3.9/site-packages/pip/_vendor/resolvelib/structs.py\", line 151, in __bool__\n",
      "    return bool(self._sequence)\n",
      "  File \"/opt/anaconda3/lib/python3.9/site-packages/pip/_internal/resolution/resolvelib/found_candidates.py\", line 140, in __bool__\n",
      "    return any(self)\n",
      "  File \"/opt/anaconda3/lib/python3.9/site-packages/pip/_internal/resolution/resolvelib/found_candidates.py\", line 128, in <genexpr>\n",
      "    return (c for c in iterator if id(c) not in self._incompatible_ids)\n",
      "  File \"/opt/anaconda3/lib/python3.9/site-packages/pip/_internal/resolution/resolvelib/found_candidates.py\", line 32, in _iter_built\n",
      "    candidate = func()\n",
      "  File \"/opt/anaconda3/lib/python3.9/site-packages/pip/_internal/resolution/resolvelib/factory.py\", line 204, in _make_candidate_from_link\n",
      "    self._link_candidate_cache[link] = LinkCandidate(\n",
      "  File \"/opt/anaconda3/lib/python3.9/site-packages/pip/_internal/resolution/resolvelib/candidates.py\", line 295, in __init__\n",
      "    super().__init__(\n",
      "  File \"/opt/anaconda3/lib/python3.9/site-packages/pip/_internal/resolution/resolvelib/candidates.py\", line 156, in __init__\n",
      "    self.dist = self._prepare()\n",
      "  File \"/opt/anaconda3/lib/python3.9/site-packages/pip/_internal/resolution/resolvelib/candidates.py\", line 227, in _prepare\n",
      "    dist = self._prepare_distribution()\n",
      "  File \"/opt/anaconda3/lib/python3.9/site-packages/pip/_internal/resolution/resolvelib/candidates.py\", line 305, in _prepare_distribution\n",
      "    return self._factory.preparer.prepare_linked_requirement(\n",
      "  File \"/opt/anaconda3/lib/python3.9/site-packages/pip/_internal/operations/prepare.py\", line 508, in prepare_linked_requirement\n",
      "    return self._prepare_linked_requirement(req, parallel_builds)\n",
      "  File \"/opt/anaconda3/lib/python3.9/site-packages/pip/_internal/operations/prepare.py\", line 550, in _prepare_linked_requirement\n",
      "    local_file = unpack_url(\n",
      "  File \"/opt/anaconda3/lib/python3.9/site-packages/pip/_internal/operations/prepare.py\", line 239, in unpack_url\n",
      "    file = get_http_url(\n",
      "  File \"/opt/anaconda3/lib/python3.9/site-packages/pip/_internal/operations/prepare.py\", line 102, in get_http_url\n",
      "    from_path, content_type = download(link, temp_dir.path)\n",
      "  File \"/opt/anaconda3/lib/python3.9/site-packages/pip/_internal/network/download.py\", line 145, in __call__\n",
      "    for chunk in chunks:\n",
      "  File \"/opt/anaconda3/lib/python3.9/site-packages/pip/_internal/cli/progress_bars.py\", line 144, in iter\n",
      "    for x in it:\n",
      "  File \"/opt/anaconda3/lib/python3.9/site-packages/pip/_internal/network/utils.py\", line 63, in response_chunks\n",
      "    for chunk in response.raw.stream(\n",
      "  File \"/opt/anaconda3/lib/python3.9/site-packages/pip/_vendor/urllib3/response.py\", line 576, in stream\n",
      "    data = self.read(amt=amt, decode_content=decode_content)\n",
      "  File \"/opt/anaconda3/lib/python3.9/site-packages/pip/_vendor/urllib3/response.py\", line 541, in read\n",
      "    raise IncompleteRead(self._fp_bytes_read, self.length_remaining)\n",
      "  File \"/opt/anaconda3/lib/python3.9/contextlib.py\", line 137, in __exit__\n",
      "    self.gen.throw(typ, value, traceback)\n",
      "  File \"/opt/anaconda3/lib/python3.9/site-packages/pip/_vendor/urllib3/response.py\", line 443, in _error_catcher\n",
      "    raise ReadTimeoutError(self._pool, None, \"Read timed out.\")\n",
      "pip._vendor.urllib3.exceptions.ReadTimeoutError: HTTPSConnectionPool(host='files.pythonhosted.org', port=443): Read timed out.\u001b[0m\n",
      "Note: you may need to restart the kernel to use updated packages.\n"
     ]
    }
   ],
   "source": [
    "pip install pandas_profiling"
   ]
  },
  {
   "cell_type": "code",
   "execution_count": null,
   "id": "c98ce383",
   "metadata": {},
   "outputs": [],
   "source": []
  }
 ],
 "metadata": {
  "kernelspec": {
   "display_name": "Python 3 (ipykernel)",
   "language": "python",
   "name": "python3"
  },
  "language_info": {
   "codemirror_mode": {
    "name": "ipython",
    "version": 3
   },
   "file_extension": ".py",
   "mimetype": "text/x-python",
   "name": "python",
   "nbconvert_exporter": "python",
   "pygments_lexer": "ipython3",
   "version": "3.9.7"
  }
 },
 "nbformat": 4,
 "nbformat_minor": 5
}
